<?xml version="1.0" ?>
<robot name="Robot">
  <!--Generated by RobotCAD, a ROS Workbench for FreeCAD (https://github.com/drfenixion/freecad.robotcad)-->
  <link name="l_Spider_trail001">
    <visual>
      <!--Spider_trail001/Spider_trail001.-->
      <origin rpy="0 0 3.141592653589793" xyz="0.0144527 0.000805453 -0.0565"/>
      <geometry>
        <mesh filename="package://spider/meshes/robotcad_simple_parts_spider_trail_qdkuwm.dae"/>
      </geometry>
    </visual>
    <collision>
      <!--col__l_Spider_trail001__col_Spider_trail__BoundBox/col_Spider_trail__BoundBox.-->
      <origin rpy="0 0 0" xyz="-0.0240473 5.54532e-05 0.0155"/>
      <geometry>
        <box size="0.179 0.05700000000000002 0.031"/>
      </geometry>
    </collision>
    <inertial>
      <mass value="0.044"/>
      <origin rpy="0 0 0" xyz="0.0 0.0 0.0"/>
      <inertia ixx="0.000083" ixy="0.0" ixz="0.0" iyy="0.000083" iyz="0.0" izz="0.000083"/>
    </inertial>
  </link>
  <link name="l_Spider_base001">
    <visual>
      <!--Spider_base001/Spider_base001.-->
      <origin rpy="0 0 0" xyz="0.2 0.2 0.2"/>
      <geometry>
        <mesh filename="package://spider/meshes/robotcad_simple_parts_spider_base_monhri.dae"/>
      </geometry>
    </visual>
    <collision>
      <!--col__l_Spider_base001__col_Spider_base__BoundBox/col_Spider_base__BoundBox.-->
      <origin rpy="0 0 0" xyz="0.199292 0.200708 0.258653"/>
      <geometry>
        <box size="0.11317322158813477 0.11317322158813477 0.014693019866943359"/>
      </geometry>
    </collision>
    <inertial>
      <mass value="0.04"/>
      <origin rpy="0 0 0" xyz="0.0 0.0 0.0"/>
      <inertia ixx="0.000083" ixy="0.0" ixz="0.0" iyy="0.000083" iyz="0.0" izz="0.000083"/>
    </inertial>
  </link>
  <link name="l_SG_base001">
    <visual>
      <!--SG_base001/SG_base001.-->
      <origin rpy="0 0 0" xyz="-0.0008725 -0.0054 -0.01816"/>
      <geometry>
        <mesh filename="package://spider/meshes/robotcad_simple_parts_sg_base_b572c8.dae"/>
      </geometry>
    </visual>
    <collision>
      <!--col__l_SG_base001__col_SG_base__BoundBox/col_SG_base__BoundBox.-->
      <origin rpy="0 0 0" xyz="0.0109475 0.00052 -0.00402"/>
      <geometry>
        <box size="0.03215000057220459 0.01184000015258789 0.028280000686645507"/>
      </geometry>
    </collision>
    <inertial>
      <mass value="0.012"/>
      <origin rpy="0 0 0" xyz="0.0 0.0 0.0"/>
      <inertia ixx="0.000083" ixy="0.0" ixz="0.0" iyy="0.000083" iyz="0.0" izz="0.000083"/>
    </inertial>
  </link>
  <link name="l_Spider_camera_module004">
    <visual>
      <!--Spider_camera_module004/Spider_camera_module005.-->
      <origin rpy="0 0.0320177076978226 0" xyz="-0.0772411 -0.0005 -0.070064"/>
      <geometry>
        <mesh filename="package://spider/meshes/robotcad_simple_parts_spider_camera_module003_cewph9.dae"/>
      </geometry>
    </visual>
    <collision>
      <!--col__l_Spider_camera_module004__col_Spider_camera_module004__BoundBox/col_Spider_camera_module004__BoundBox.-->
      <origin rpy="0 0.0320177076978226 0" xyz="-0.000915109 0.0 0.00803265"/>
      <geometry>
        <box size="0.018426376342773436 0.026 0.019"/>
      </geometry>
    </collision>
    <inertial>
      <mass value="0.001"/>
      <origin rpy="0 0 0" xyz="0.0 0.0 0.0"/>
      <inertia ixx="0.000083" ixy="0.0" ixz="0.0" iyy="0.000083" iyz="0.0" izz="0.000083"/>
    </inertial>
  </link>
  <link name="l_Spider_cupula_superior_camera004">
    <visual>
      <!--Spider_cupula_superior_camera004/Spider_cupula_superior_camera005.-->
      <origin rpy="0 0 0" xyz="0.011 -0.011 -0.1425"/>
      <geometry>
        <mesh filename="package://spider/meshes/robotcad_simple_parts_spider_cupula_superior_camera003_ep25yw.dae"/>
      </geometry>
    </visual>
    <collision>
      <!--col__l_Spider_cupula_superior_camera004__col_Spider_cupula_superior_camera004__BoundBox/col_Spider_cupula_superior_camera004__BoundBox.-->
      <origin rpy="0 0 0" xyz="0.011 -0.011 -0.0345202"/>
      <geometry>
        <box size="0.15 0.14995338439941405 0.0747596206665039"/>
      </geometry>
    </collision>
    <inertial>
      <mass value="0.220"/>
      <origin rpy="0 0 0" xyz="0.0 0.0 0.0"/>
      <inertia ixx="0.000083" ixy="0.0" ixz="0.0" iyy="0.000083" iyz="0.0" izz="0.000083"/>
    </inertial>
  </link>
  <link name="l_Spider_cupula_in_servo_25T_5_005">
    <visual>
      <!--Spider_cupula_in_servo_25T_5_005/Spider_cupula_in_servo_25T_5_006.-->
      <origin rpy="0 0 0" xyz="0.0 0.0 -0.074087"/>
      <geometry>
        <mesh filename="package://spider/meshes/robotcad_simple_parts_spider_cupula_in_servo_25t_5_004_ehdugy.dae"/>
      </geometry>
    </visual>
    <inertial>
      <mass value="0.061"/>
      <origin rpy="0 0 0" xyz="0.0 0.0 0.0"/>
      <inertia ixx="0.000083" ixy="0.0" ixz="0.0" iyy="0.000083" iyz="0.0" izz="0.000083"/>
    </inertial>
  </link>
  <link name="l_Spider_hip_backright001">
    <visual>
      <!--Spider_hip_backright001/Spider_hip_backright001.-->
      <origin rpy="0 0 0" xyz="0.0 -0.04175 -0.042"/>
      <geometry>
        <mesh filename="package://spider/meshes/robotcad_simple_parts_spider_hip_backright_luxmtj.dae"/>
      </geometry>
    </visual>
    <collision>
      <!--col__l_Spider_hip_backright001__col_Spider_hip_backright__BoundBox/col_Spider_hip_backright__BoundBox.-->
      <origin rpy="0 0 0" xyz="-0.0015 -0.02525 -0.021"/>
      <geometry>
        <box size="0.027 0.057 0.042"/>
      </geometry>
    </collision>
    <inertial>
      <mass value="0.022"/>
      <origin rpy="0 0 0" xyz="0.0 0.0 0.0"/>
      <inertia ixx="0.000083" ixy="0.0" ixz="0.0" iyy="0.000083" iyz="0.0" izz="0.000083"/>
    </inertial>
  </link>
  <link name="l_SG_hip_back_right001">
    <visual>
      <!--SG_hip_back_right001/SG_hip_back_right001.-->
      <origin rpy="0 0 0" xyz="-0.019 -0.00592 -0.02828"/>
      <geometry>
        <mesh filename="package://spider/meshes/robotcad_simple_parts_sg_hip_back_right_fdelkm.dae"/>
      </geometry>
    </visual>
    <collision>
      <!--col__l_SG_hip_back_right001__col_SG_hip_back_right__BoundBox/col_SG_hip_back_right__BoundBox.-->
      <origin rpy="0 0 0" xyz="-0.00718 0.0 -0.01414"/>
      <geometry>
        <box size="0.03215000057220459 0.01184000015258789 0.028280000686645507"/>
      </geometry>
    </collision>
    <inertial>
      <mass value="0.012"/>
      <origin rpy="0 0 0" xyz="0.0 0.0 0.0"/>
      <inertia ixx="0.000083" ixy="0.0" ixz="0.0" iyy="0.000083" iyz="0.0" izz="0.000083"/>
    </inertial>
  </link>
  <link name="l_SG_hip_back_left001">
    <visual>
      <!--SG_hip_back_left001/SG_hip_back_left001.-->
      <origin rpy="0 0 0" xyz="-0.019 -0.00592 -0.02828"/>
      <geometry>
        <mesh filename="package://spider/meshes/robotcad_simple_parts_sg_hip_back_left_5euasu.dae"/>
      </geometry>
    </visual>
    <collision>
      <!--col__l_SG_hip_back_left001__col_SG_hip_back_left__BoundBox/col_SG_hip_back_left__BoundBox.-->
      <origin rpy="0 0 0" xyz="-0.00718 0.0 -0.01414"/>
      <geometry>
        <box size="0.03215000057220459 0.01184000015258789 0.028280000686645507"/>
      </geometry>
    </collision>
    <inertial>
      <mass value="0.012"/>
      <origin rpy="0 0 0" xyz="0.0 0.0 0.0"/>
      <inertia ixx="0.000083" ixy="0.0" ixz="0.0" iyy="0.000083" iyz="0.0" izz="0.000083"/>
    </inertial>
  </link>
  <link name="l_Spider_hip_backleft001">
    <visual>
      <!--Spider_hip_backleft001/Spider_hip_backleft001.-->
      <origin rpy="0 0 0" xyz="0.0 -0.04175 -0.042"/>
      <geometry>
        <mesh filename="package://spider/meshes/robotcad_simple_parts_spider_hip_backleft_tgmhk1.dae"/>
      </geometry>
    </visual>
    <collision>
      <!--col__l_Spider_hip_backleft001__col_Spider_hip_backleft__BoundBox/col_Spider_hip_backleft__BoundBox.-->
      <origin rpy="0 0 0" xyz="-0.0015 -0.02525 -0.021"/>
      <geometry>
        <box size="0.027 0.057 0.042"/>
      </geometry>
    </collision>
    <inertial>
      <mass value="0.022"/>
      <origin rpy="0 0 0" xyz="0.0 0.0 0.0"/>
      <inertia ixx="0.000083" ixy="0.0" ixz="0.0" iyy="0.000083" iyz="0.0" izz="0.000083"/>
    </inertial>
  </link>
  <link name="l_Spider_hip_frontright001">
    <visual>
      <!--Spider_hip_frontright001/Spider_hip_frontright001.-->
      <origin rpy="0 0 0" xyz="9.15879e-05 -0.0417476 -0.042"/>
      <geometry>
        <mesh filename="package://spider/meshes/robotcad_simple_parts_spider_hip_frontright_r7e61f.dae"/>
      </geometry>
    </visual>
    <collision>
      <!--col__l_Spider_hip_frontright001__col_Spider_hip_frontright__BoundBox/col_Spider_hip_frontright__BoundBox.-->
      <origin rpy="0 0 0" xyz="-0.00140841 -0.0252476 -0.021"/>
      <geometry>
        <box size="0.027 0.057 0.042"/>
      </geometry>
    </collision>
    <inertial>
      <mass value="0.022"/>
      <origin rpy="0 0 0" xyz="0.0 0.0 0.0"/>
      <inertia ixx="0.000083" ixy="0.0" ixz="0.0" iyy="0.000083" iyz="0.0" izz="0.000083"/>
    </inertial>
  </link>
  <link name="l_SG_hip_front_right001">
    <visual>
      <!--SG_hip_front_right001/SG_hip_front_right001.-->
      <origin rpy="0 0 0" xyz="-0.019 -0.00592 -0.02828"/>
      <geometry>
        <mesh filename="package://spider/meshes/robotcad_simple_parts_sg_hip_front_right_s1hwve.dae"/>
      </geometry>
    </visual>
    <collision>
      <!--col__l_SG_hip_front_right001__col_SG_hip_front_right__BoundBox/col_SG_hip_front_right__BoundBox.-->
      <origin rpy="0 0 0" xyz="-0.00718 0.0 -0.01414"/>
      <geometry>
        <box size="0.03215000057220459 0.01184000015258789 0.028280000686645507"/>
      </geometry>
    </collision>
    <inertial>
      <mass value="0.012"/>
      <origin rpy="0 0 0" xyz="0.0 0.0 0.0"/>
      <inertia ixx="0.000083" ixy="0.0" ixz="0.0" iyy="0.000083" iyz="0.0" izz="0.000083"/>
    </inertial>
  </link>
  <link name="l_Spider_hip_frontleft001">
    <visual>
      <!--Spider_hip_frontleft001/Spider_hip_frontleft001.-->
      <origin rpy="0 0 0" xyz="0.0 -0.04175 -0.042"/>
      <geometry>
        <mesh filename="package://spider/meshes/robotcad_simple_parts_spider_hip_frontleft_rgxnoo.dae"/>
      </geometry>
    </visual>
    <collision>
      <!--col__l_Spider_hip_frontleft001__col_Spider_hip_frontleft__BoundBox/col_Spider_hip_frontleft__BoundBox.-->
      <origin rpy="0 0 0" xyz="-0.0015 -0.02525 -0.021"/>
      <geometry>
        <box size="0.027 0.057 0.042"/>
      </geometry>
    </collision>
    <inertial>
      <mass value="0.022"/>
      <origin rpy="0 0 0" xyz="0.0 0.0 0.0"/>
      <inertia ixx="0.000083" ixy="0.0" ixz="0.0" iyy="0.000083" iyz="0.0" izz="0.000083"/>
    </inertial>
  </link>
  <link name="l_SG_hip_front_left001">
    <visual>
      <!--SG_hip_front_left001/SG_hip_front_left001.-->
      <origin rpy="0 0 0" xyz="-0.019 -0.00592 -0.02828"/>
      <geometry>
        <mesh filename="package://spider/meshes/robotcad_simple_parts_sg_hip_front_left_oclyju.dae"/>
      </geometry>
    </visual>
    <collision>
      <!--col__l_SG_hip_front_left001__col_SG_hip_front_left__BoundBox/col_SG_hip_front_left__BoundBox.-->
      <origin rpy="0 0 0" xyz="-0.00718 0.0 -0.01414"/>
      <geometry>
        <box size="0.03215000057220459 0.01184000015258789 0.028280000686645507"/>
      </geometry>
    </collision>
    <inertial>
      <mass value="0.012"/>
      <origin rpy="0 0 0" xyz="0.0 0.0 0.0"/>
      <inertia ixx="0.000083" ixy="0.0" ixz="0.0" iyy="0.000083" iyz="0.0" izz="0.000083"/>
    </inertial>
  </link>
  <link name="l_Spider_hipleg_backright001">
    <visual>
      <!--Spider_hipleg_backright001/Spider_hipleg_backright001.-->
      <origin rpy="0 0 0" xyz="0.00568485 -0.000145071 -0.022"/>
      <geometry>
        <mesh filename="package://spider/meshes/robotcad_simple_parts_spider_hipleg_backright_pe2cqp.dae"/>
      </geometry>
    </visual>
    <collision>
      <!--col__l_Spider_hipleg_backright001__col_Spider_hipleg_backright__BoundBox/col_Spider_hipleg_backright__BoundBox.-->
      <origin rpy="0 0 0" xyz="-0.0109703 -0.000145071 -0.01"/>
      <geometry>
        <box size="0.061189601898193356 0.0425 0.024"/>
      </geometry>
    </collision>
    <inertial>
      <mass value="0.015"/>
      <origin rpy="0 0 0" xyz="0.0 0.0 0.0"/>
      <inertia ixx="0.000083" ixy="0.0" ixz="0.0" iyy="0.000083" iyz="0.0" izz="0.000083"/>
    </inertial>
  </link>
  <link name="l_SG_leg_back_right001">
    <visual>
      <!--SG_leg_back_right001/SG_leg_back_right001.-->
      <origin rpy="0 0 0" xyz="-0.015 -0.00592 -0.02828"/>
      <geometry>
        <mesh filename="package://spider/meshes/robotcad_simple_parts_sg_leg_back_right_5utyh4.dae"/>
      </geometry>
    </visual>
    <collision>
      <!--col__l_SG_leg_back_right001__col_SG_leg_back_right__BoundBox/col_SG_leg_back_right__BoundBox.-->
      <origin rpy="0 0 0" xyz="-0.00318 0.0 -0.01414"/>
      <geometry>
        <box size="0.03215000057220459 0.01184000015258789 0.028280000686645507"/>
      </geometry>
    </collision>
    <inertial>
      <mass value="0.012"/>
      <origin rpy="0 0 0" xyz="0.0 0.0 0.0"/>
      <inertia ixx="0.000083" ixy="0.0" ixz="0.0" iyy="0.000083" iyz="0.0" izz="0.000083"/>
    </inertial>
  </link>
  <link name="l_Spider_hipleg_backleft001">
    <visual>
      <!--Spider_hipleg_backleft001/Spider_hipleg_backleft001.-->
      <origin rpy="0 0 0" xyz="0.00568485 -0.000145071 -0.022"/>
      <geometry>
        <mesh filename="package://spider/meshes/robotcad_simple_parts_spider_hipleg_backleft_obk77e.dae"/>
      </geometry>
    </visual>
    <collision>
      <!--col__l_Spider_hipleg_backleft001__col_Spider_hipleg_backleft__BoundBox/col_Spider_hipleg_backleft__BoundBox.-->
      <origin rpy="0 0 0" xyz="-0.0109703 -0.000145071 -0.01"/>
      <geometry>
        <box size="0.061189601898193356 0.0425 0.024"/>
      </geometry>
    </collision>
    <inertial>
      <mass value="0.015"/>
      <origin rpy="0 0 0" xyz="0.0 0.0 0.0"/>
      <inertia ixx="0.000083" ixy="0.0" ixz="0.0" iyy="0.000083" iyz="0.0" izz="0.000083"/>
    </inertial>
  </link>
  <link name="l_SG_leg_back_left001">
    <visual>
      <!--SG_leg_back_left001/SG_leg_back_left001.-->
      <origin rpy="0 0 0" xyz="-0.015 -0.00592 -0.02828"/>
      <geometry>
        <mesh filename="package://spider/meshes/robotcad_simple_parts_sg_leg_back_left_lz21vq.dae"/>
      </geometry>
    </visual>
    <collision>
      <!--col__l_SG_leg_back_left001__col_SG_leg_back_left__BoundBox/col_SG_leg_back_left__BoundBox.-->
      <origin rpy="0 0 0" xyz="-0.00318 0.0 -0.01414"/>
      <geometry>
        <box size="0.03215000057220459 0.01184000015258789 0.028280000686645507"/>
      </geometry>
    </collision>
    <inertial>
      <mass value="0.012"/>
      <origin rpy="0 0 0" xyz="0.0 0.0 0.0"/>
      <inertia ixx="0.000083" ixy="0.0" ixz="0.0" iyy="0.000083" iyz="0.0" izz="0.000083"/>
    </inertial>
  </link>
  <link name="l_Spider_hipleg_frontright001">
    <visual>
      <!--Spider_hipleg_frontright001/Spider_hipleg_frontright001.-->
      <origin rpy="0 0 0" xyz="0.00568485 -0.000145071 -0.022"/>
      <geometry>
        <mesh filename="package://spider/meshes/robotcad_simple_parts_spider_hipleg_frontright_gtg3oi.dae"/>
      </geometry>
    </visual>
    <collision>
      <!--col__l_Spider_hipleg_frontright001__col_Spider_hipleg_frontright__BoundBox/col_Spider_hipleg_frontright__BoundBox.-->
      <origin rpy="0 0 0" xyz="-0.0109703 -0.000145071 -0.01"/>
      <geometry>
        <box size="0.061189601898193356 0.0425 0.024"/>
      </geometry>
    </collision>
    <inertial>
      <mass value="0.015"/>
      <origin rpy="0 0 0" xyz="0.0 0.0 0.0"/>
      <inertia ixx="0.000083" ixy="0.0" ixz="0.0" iyy="0.000083" iyz="0.0" izz="0.000083"/>
    </inertial>
  </link>
  <link name="l_SG_leg_front_right001">
    <visual>
      <!--SG_leg_front_right001/SG_leg_front_right001.-->
      <origin rpy="0 0 0" xyz="-0.015 -0.00592 -0.02828"/>
      <geometry>
        <mesh filename="package://spider/meshes/robotcad_simple_parts_sg_leg_front_right_txxlih.dae"/>
      </geometry>
    </visual>
    <collision>
      <!--col__l_SG_leg_front_right001__col_SG_leg_front_right__BoundBox/col_SG_leg_front_right__BoundBox.-->
      <origin rpy="0 0 0" xyz="-0.00318 0.0 -0.01414"/>
      <geometry>
        <box size="0.03215000057220459 0.01184000015258789 0.028280000686645507"/>
      </geometry>
    </collision>
    <inertial>
      <mass value="0.012"/>
      <origin rpy="0 0 0" xyz="0.0 0.0 0.0"/>
      <inertia ixx="0.000083" ixy="0.0" ixz="0.0" iyy="0.000083" iyz="0.0" izz="0.000083"/>
    </inertial>
  </link>
  <link name="l_Spider_hipleg_frontleft001">
    <visual>
      <!--Spider_hipleg_frontleft001/Spider_hipleg_frontleft001.-->
      <origin rpy="0 0 0" xyz="0.00568485 -0.000145071 -0.022"/>
      <geometry>
        <mesh filename="package://spider/meshes/robotcad_simple_parts_spider_hipleg_frontleft_vysar6.dae"/>
      </geometry>
    </visual>
    <collision>
      <!--col__l_Spider_hipleg_frontleft001__col_Spider_hipleg_frontleft__BoundBox/col_Spider_hipleg_frontleft__BoundBox.-->
      <origin rpy="0 0 0" xyz="-0.0109703 -0.000145071 -0.01"/>
      <geometry>
        <box size="0.061189601898193356 0.0425 0.024"/>
      </geometry>
    </collision>
    <inertial>
      <mass value="0.015"/>
      <origin rpy="0 0 0" xyz="0.0 0.0 0.0"/>
      <inertia ixx="0.000083" ixy="0.0" ixz="0.0" iyy="0.000083" iyz="0.0" izz="0.000083"/>
    </inertial>
  </link>
  <link name="l_SG_leg_front_left001">
    <visual>
      <!--SG_leg_front_left001/SG_leg_front_left001.-->
      <origin rpy="0 0 0" xyz="-0.015 -0.00592 -0.02828"/>
      <geometry>
        <mesh filename="package://spider/meshes/robotcad_simple_parts_sg_leg_front_left_1neb7v.dae"/>
      </geometry>
    </visual>
    <collision>
      <!--col__l_SG_leg_front_left001__col_SG_leg_front_left__BoundBox/col_SG_leg_front_left__BoundBox.-->
      <origin rpy="0 0 0" xyz="-0.00318 0.0 -0.01414"/>
      <geometry>
        <box size="0.03215000057220459 0.01184000015258789 0.028280000686645507"/>
      </geometry>
    </collision>
    <inertial>
      <mass value="0.012"/>
      <origin rpy="0 0 0" xyz="0.0 0.0 0.0"/>
      <inertia ixx="0.000083" ixy="0.0" ixz="0.0" iyy="0.000083" iyz="0.0" izz="0.000083"/>
    </inertial>
  </link>
  <link name="l_Spider_leg_backright001">
    <visual>
      <!--Spider_leg_backright001/Spider_leg_backright001.-->
      <origin rpy="-1.5707963267948963 -1.5707963267948961 0" xyz="-0.0041101 -0.01225 0.02235"/>
      <geometry>
        <mesh filename="package://spider/meshes/robotcad_simple_parts_spider_leg_backright_lrtlkg.dae"/>
      </geometry>
    </visual>
    <collision>
      <!--col__l_Spider_leg_backright001__col_Spider_leg_backright__BoundBox/col_Spider_leg_backright__BoundBox.-->
      <origin rpy="-1.5707963267948963 -1.5707963267948961 0" xyz="0.00910683 -0.00025 -0.00585612"/>
      <geometry>
        <box size="0.07363168144226075 0.041541129112243655 0.024"/>
      </geometry>
    </collision>
    <inertial>
      <mass value="0.017"/>
      <origin rpy="0 0 0" xyz="0.0 0.0 0.0"/>
      <inertia ixx="0.000083" ixy="0.0" ixz="0.0" iyy="0.000083" iyz="0.0" izz="0.000083"/>
    </inertial>
  </link>
  <link name="l_SG_foot_back_right001">
    <visual>
      <!--SG_foot_back_right001/SG_foot_back_right001.-->
      <origin rpy="0 0 0.6981317007977319" xyz="-0.011054 -0.01592 0.000642788"/>
      <geometry>
        <mesh filename="package://spider/meshes/robotcad_simple_parts_sg_foot_back_right_ncknri.dae"/>
      </geometry>
    </visual>
    <collision>
      <!--col__l_SG_foot_back_right001__col_SG_foot_back_right__BoundBox/col_SG_foot_back_right__BoundBox.-->
      <origin rpy="-1.5707963267948966 -0.6981317007977316 0" xyz="-0.00497123 -0.00378727 0.0117896"/>
      <geometry>
        <box size="0.03530946667937766 0.0325389757123584 0.029735588342646075"/>
      </geometry>
    </collision>
    <inertial>
      <mass value="0.012"/>
      <origin rpy="0 0 0" xyz="0.0 0.0 0.0"/>
      <inertia ixx="0.000083" ixy="0.0" ixz="0.0" iyy="0.000083" iyz="0.0" izz="0.000083"/>
    </inertial>
  </link>
  <link name="l_Spider_leg_backleft001">
    <visual>
      <!--Spider_leg_backleft001/Spider_leg_backleft001.-->
      <origin rpy="0 0 0" xyz="0.0107247 -0.00394229 -0.022"/>
      <geometry>
        <mesh filename="package://spider/meshes/robotcad_simple_parts_spider_leg_backleft_lcqqwg.dae"/>
      </geometry>
    </visual>
    <collision>
      <!--col__l_Spider_leg_backleft001__col_Spider_leg_backleft__BoundBox/col_Spider_leg_backleft__BoundBox.-->
      <origin rpy="0 0 0" xyz="-0.0174815 0.00927465 -0.01"/>
      <geometry>
        <box size="0.07363168144226075 0.041541129112243655 0.024"/>
      </geometry>
    </collision>
    <inertial>
      <mass value="0.017"/>
      <origin rpy="0 0 0" xyz="0.0 0.0 0.0"/>
      <inertia ixx="0.000083" ixy="0.0" ixz="0.0" iyy="0.000083" iyz="0.0" izz="0.000083"/>
    </inertial>
  </link>
  <link name="l_SG_foot_back_left001">
    <visual>
      <!--SG_foot_back_left001/SG_foot_back_left001.-->
      <origin rpy="-1.5707963267948961 -1.5707963267948963 0" xyz="-0.00592 -0.00828 0.0"/>
      <geometry>
        <mesh filename="package://spider/meshes/robotcad_simple_parts_sg_foot_back_left_mesfke.dae"/>
      </geometry>
    </visual>
    <collision>
      <!--col__l_SG_foot_back_left001__col_SG_foot_back_left__BoundBox/col_SG_foot_back_left__BoundBox.-->
      <origin rpy="-1.5707963267948961 -1.5707963267948963 0" xyz="0.0 0.00586 0.01182"/>
      <geometry>
        <box size="0.03215000057220459 0.01184000015258789 0.028280000686645507"/>
      </geometry>
    </collision>
    <inertial>
      <mass value="0.012"/>
      <origin rpy="0 0 0" xyz="0.0 0.0 0.0"/>
      <inertia ixx="0.000083" ixy="0.0" ixz="0.0" iyy="0.000083" iyz="0.0" izz="0.000083"/>
    </inertial>
  </link>
  <link name="l_Spider_leg_frontright001">
    <visual>
      <!--Spider_leg_frontright001/Spider_leg_frontright001.-->
      <origin rpy="0 0 0" xyz="0.0107247 -0.00394229 -0.022"/>
      <geometry>
        <mesh filename="package://spider/meshes/robotcad_simple_parts_spider_leg_frontright_4yyn4h.dae"/>
      </geometry>
    </visual>
    <collision>
      <!--col__l_Spider_leg_frontright001__col_Spider_leg_frontright__BoundBox/col_Spider_leg_frontright__BoundBox.-->
      <origin rpy="0 0 0" xyz="-0.0174815 0.00927465 -0.01"/>
      <geometry>
        <box size="0.07363168144226075 0.041541129112243655 0.024"/>
      </geometry>
    </collision>
    <inertial>
      <mass value="0.017"/>
      <origin rpy="0 0 0" xyz="0.0 0.0 0.0"/>
      <inertia ixx="0.000083" ixy="0.0" ixz="0.0" iyy="0.000083" iyz="0.0" izz="0.000083"/>
    </inertial>
  </link>
  <link name="l_SG_foot_front_right001">
    <visual>
      <!--SG_foot_front_right001/SG_foot_front_right001.-->
      <origin rpy="-1.5707963267948963 -1.5707963267948961 0" xyz="-0.00592 -0.00828 0.0"/>
      <geometry>
        <mesh filename="package://spider/meshes/robotcad_simple_parts_sg_foot_front_right_2f7ujs.dae"/>
      </geometry>
    </visual>
    <collision>
      <!--col__l_SG_foot_front_right001__col_SG_foot_front_right__BoundBox/col_SG_foot_front_right__BoundBox.-->
      <origin rpy="-1.5707963267948963 -1.5707963267948961 0" xyz="0.0 0.00586 0.01182"/>
      <geometry>
        <box size="0.03215000057220459 0.01184000015258789 0.028280000686645507"/>
      </geometry>
    </collision>
    <inertial>
      <mass value="0.012"/>
      <origin rpy="0 0 0" xyz="0.0 0.0 0.0"/>
      <inertia ixx="0.000083" ixy="0.0" ixz="0.0" iyy="0.000083" iyz="0.0" izz="0.000083"/>
    </inertial>
  </link>
  <link name="l_Spider_leg_frontleft001">
    <visual>
      <!--Spider_leg_frontleft001/Spider_leg_frontleft001.-->
      <origin rpy="0 0 0" xyz="0.0107247 -0.00394229 -0.022"/>
      <geometry>
        <mesh filename="package://spider/meshes/robotcad_simple_parts_spider_leg_frontleft_jyrr3v.dae"/>
      </geometry>
    </visual>
    <collision>
      <!--col__l_Spider_leg_frontleft001__col_Spider_leg_frontleft__BoundBox/col_Spider_leg_frontleft__BoundBox.-->
      <origin rpy="0 0 0" xyz="-0.0174815 0.00927465 -0.01"/>
      <geometry>
        <box size="0.07363168144226075 0.041541129112243655 0.024"/>
      </geometry>
    </collision>
    <inertial>
      <mass value="0.017"/>
      <origin rpy="0 0 0" xyz="0.0 0.0 0.0"/>
      <inertia ixx="0.000083" ixy="0.0" ixz="0.0" iyy="0.000083" iyz="0.0" izz="0.000083"/>
    </inertial>
  </link>
  <link name="l_SG_foot_front_left001">
    <visual>
      <!--SG_foot_front_left001/SG_foot_front_left001.-->
      <origin rpy="-1.570796326794896 -1.5707963267948961 0" xyz="-0.00592 -0.00828 0.0"/>
      <geometry>
        <mesh filename="package://spider/meshes/robotcad_simple_parts_sg_foot_front_left_sx0cyl.dae"/>
      </geometry>
    </visual>
    <collision>
      <!--col__l_SG_foot_front_left001__col_SG_foot_front_left__BoundBox/col_SG_foot_front_left__BoundBox.-->
      <origin rpy="-1.570796326794896 -1.5707963267948961 0" xyz="0.0 0.00586 0.01182"/>
      <geometry>
        <box size="0.03215000057220459 0.01184000015258789 0.028280000686645507"/>
      </geometry>
    </collision>
    <inertial>
      <mass value="0.012"/>
      <origin rpy="0 0 0" xyz="0.0 0.0 0.0"/>
      <inertia ixx="0.000083" ixy="0.0" ixz="0.0" iyy="0.000083" iyz="0.0" izz="0.000083"/>
    </inertial>
  </link>
  <link name="l_Spider_foot_frontleft001">
    <visual>
      <!--Spider_foot_frontleft001/Spider_foot_frontleft001.-->
      <origin rpy="1.570796326794897 0 -1.0471975511965976" xyz="-0.000214978 2.81452e-05 -0.00625"/>
      <geometry>
        <mesh filename="package://spider/meshes/robotcad_simple_parts_spider_foot_frontleft_twfqzz.dae"/>
      </geometry>
      <material name="gray">
          <color rgba="0.6 0.6 0.6 1.0"/>
      </material>
    </visual>
    <collision>
      <!--col__l_Spider_foot_frontleft001__col_Spider_foot_frontleft__BoundBox/col_Spider_foot_frontleft__BoundBox.-->
      <origin rpy="1.570796326794897 0 -1.0471975511965976" xyz="0.0309048 0.0232785 0.0156888"/>
      <geometry>
        <box size="0.03414908027648926 0.05486522340774536 0.10214860916137695"/>
      </geometry>
    </collision>
    <inertial>
      <mass value="0.031"/>
      <origin rpy="0 0 0" xyz="0.0 0.0 0.0"/>
      <inertia ixx="0.000083" ixy="0.0" ixz="0.0" iyy="0.000083" iyz="0.0" izz="0.000083"/>
    </inertial>
  </link>
  <link name="l_Spider_foot_frontright001">
    <visual>
      <!--Spider_foot_frontright001/Spider_foot_frontright001.-->
      <origin rpy="1.5707963267948968 0 0" xyz="-0.000131863 -0.000172104 -0.00625"/>
      <geometry>
        <mesh filename="package://spider/meshes/robotcad_simple_parts_spider_foot_frontright_kumujr.dae"/>
      </geometry>
    </visual>
    <collision>
      <!--col__l_Spider_foot_frontright001__col_Spider_foot_frontright__BoundBox/col_Spider_foot_frontright__BoundBox.-->
      <origin rpy="1.5707963267948968 0 0" xyz="-0.00470732 0.0384036 0.0156888"/>
      <geometry>
        <box size="0.03414908027648926 0.05486522340774536 0.10214860916137695"/>
      </geometry>
    </collision>
    <inertial>
      <mass value="0.031"/>
      <origin rpy="0 0 0" xyz="0.0 0.0 0.0"/>
      <inertia ixx="0.000083" ixy="0.0" ixz="0.0" iyy="0.000083" iyz="0.0" izz="0.000083"/>
    </inertial>
  </link>
  <link name="l_Spider_foot_backright001">
    <visual>
      <!--Spider_foot_backright001/Spider_foot_backright001.-->
      <origin rpy="1.5707963267948968 0 0" xyz="-0.000131863 -0.000172104 -0.00625"/>
      <geometry>
        <mesh filename="package://spider/meshes/robotcad_simple_parts_spider_foot_backright_3sides.dae"/>
      </geometry>
    </visual>
    <collision>
      <!--col__l_Spider_foot_backright001__col_Spider_foot_backright__BoundBox/col_Spider_foot_backright__BoundBox.-->
      <origin rpy="1.5707963267948968 0 0" xyz="-0.00470732 0.0384036 0.0156888"/>
      <geometry>
        <box size="0.03414908027648926 0.05486522340774536 0.10214860916137695"/>
      </geometry>
    </collision>
    <inertial>
      <mass value="0.031"/>
      <origin rpy="0 0 0" xyz="0.0 0.0 0.0"/>
      <inertia ixx="0.000083" ixy="0.0" ixz="0.0" iyy="0.000083" iyz="0.0" izz="0.000083"/>
    </inertial>
  </link>
  <link name="l_Spider_foot_backleft001">
    <visual>
      <!--Spider_foot_backleft001/Spider_foot_backleft001.-->
      <origin rpy="1.5707963267948968 0 0" xyz="-0.000131863 -0.000172104 -0.00625"/>
      <geometry>
        <mesh filename="package://spider/meshes/robotcad_simple_parts_spider_foot_backleft_93slyp.dae"/>
      </geometry>
    </visual>
    <collision>
      <!--col__l_Spider_foot_backleft001__col_Spider_foot_backleft__BoundBox/col_Spider_foot_backleft__BoundBox.-->
      <origin rpy="1.5707963267948968 0 0" xyz="-0.00470732 0.0384036 0.0156888"/>
      <geometry>
        <box size="0.03414908027648926 0.05486522340774536 0.10214860916137695"/>
      </geometry>
    </collision>
    <inertial>
      <mass value="0.031"/>
      <origin rpy="0 0 0" xyz="0.0 0.0 0.0"/>
      <inertia ixx="0.000083" ixy="0.0" ixz="0.0" iyy="0.000083" iyz="0.0" izz="0.000083"/>
    </inertial>
  </link>
  <joint name="l_Spider_base001__to__l_Spider_trail001" type="fixed">
    <parent link="l_Spider_base001"/>
    <child link="l_Spider_trail001"/>
    <origin rpy="0 0 0" xyz="0.183143 0.200684 0.2565"/>
  </joint>
  <joint name="l_Spider_base001__to__l_SG_base001" type="fixed">
    <parent link="l_Spider_base001"/>
    <child link="l_SG_base001"/>
    <origin rpy="0 0 0" xyz="0.183143 0.200684 0.2645"/>
  </joint>
  <joint name="base_to_cupula" type="revolute">
    <parent link="l_SG_base001"/>
    <child link="l_Spider_cupula_in_servo_25T_5_005"/>
    <origin rpy="0 0 0" xyz="0.0161275 0.00052 0.01012"/>
    <axis xyz="0 0 1"/>
    <limit effort="0.22" lower="-3.141592653589793" upper="3.141592653589793" velocity="10.0"/>
  </joint>
  <joint name="l_Spider_cupula_in_servo_25T_5_005__to__l_Spider_cupula_superior_camera004" type="fixed">
    <parent link="l_Spider_cupula_in_servo_25T_5_005"/>
    <child link="l_Spider_cupula_superior_camera004"/>
    <origin rpy="0 0 0" xyz="-0.011 0.011 0.068413"/>
  </joint>
  <joint name="l_Spider_cupula_superior_camera004__to__l_Spider_camera_module004" type="fixed">
    <parent link="l_Spider_cupula_superior_camera004"/>
    <child link="l_Spider_camera_module004"/>
    <origin rpy="0 -0.0246003908527461 0" xyz="0.0859546 -0.011 -0.0700557"/>
  </joint>
  <joint name="l_Spider_base001__to__l_Spider_hip_backright001" type="fixed">
    <parent link="l_Spider_base001"/>
    <child link="l_Spider_hip_backright001"/>
    <origin rpy="0 0 -0.7853981633974484" xyz="0.17521 0.17643 0.25131"/>
  </joint>
  <joint name="hip_backright" type="revolute">
    <parent link="l_Spider_hip_backright001"/>
    <child link="l_SG_hip_back_right001"/>
    <origin rpy="3.141592653589793 0 1.5707963267948963" xyz="0.0 -0.04275 -0.039"/>
    <axis xyz="0 0 1"/>
    <limit effort="0.22" lower="-1.57" upper="1.57" velocity="10.0"/>
  </joint>
  <joint name="l_Spider_base001__to__l_Spider_hip_backleft001" type="fixed">
    <parent link="l_Spider_base001"/>
    <child link="l_Spider_hip_backleft001"/>
    <origin rpy="0 0 -2.356194490192345" xyz="0.17521 0.22499 0.25131"/>
  </joint>
  <joint name="hip_backleft" type="revolute">
    <parent link="l_Spider_hip_backleft001"/>
    <child link="l_SG_hip_back_left001"/>
    <origin rpy="3.141592653589793 0 1.5707963267948963" xyz="0.0 -0.0425 -0.039"/>
    <axis xyz="0 0 1"/>
    <limit effort="0.22" lower="-1.57" upper="1.57" velocity="10.0"/>
  </joint>
  <joint name="l_Spider_base001__to__l_Spider_hip_frontright001" type="fixed">
    <parent link="l_Spider_base001"/>
    <child link="l_Spider_hip_frontright001"/>
    <origin rpy="0 0 0.7853981633974484" xyz="0.22381 0.17679 0.25131"/>
  </joint>
  <joint name="hip_frontright" type="revolute">
    <parent link="l_Spider_hip_frontright001"/>
    <child link="l_SG_hip_front_right001"/>
    <origin rpy="3.141592653589793 0 1.5707963267948963" xyz="0.0 -0.0425 -0.039"/>
    <axis xyz="0 0 1"/>
    <limit effort="0.22" lower="-1.57" upper="1.57" velocity="10.0"/>
  </joint>
  <joint name="l_Spider_base001__to__l_Spider_hip_frontleft001" type="fixed">
    <parent link="l_Spider_base001"/>
    <child link="l_Spider_hip_frontleft001"/>
    <origin rpy="0 0 2.356194490192345" xyz="0.22381 0.22462 0.25131"/>
  </joint>
  <joint name="hip_frontleft" type="revolute">
    <parent link="l_Spider_hip_frontleft001"/>
    <child link="l_SG_hip_front_left001"/>
    <origin rpy="3.141592653589793 0 1.5707963267948963" xyz="0.0 -0.0425 -0.039"/>
    <axis xyz="0 0 1"/>
    <limit effort="0.22" lower="-1.57" upper="1.57" velocity="10.0"/>
  </joint>
  <joint name="l_SG_hip_back_right001__to__l_Spider_hipleg_backright001" type="fixed">
    <parent link="l_SG_hip_back_right001"/>
    <child link="l_Spider_hipleg_backright001"/>
    <origin rpy="3.141592653589793 0 0" xyz="-0.00718 0.0 -0.02828"/>
  </joint>
  <joint name="leg_backright" type="revolute">
    <parent link="l_Spider_hipleg_backright001"/>
    <child link="l_SG_leg_back_right001"/>
    <origin rpy="1.5707963267948963 0 0" xyz="-0.03857 -0.0175 -0.01"/>
    <axis xyz="0 0 1"/>
    <limit effort="0.22" lower="-1.57" upper="1.57" velocity="10.0"/>
  </joint>
  <joint name="l_SG_hip_back_left001__to__l_Spider_hipleg_backleft001" type="fixed">
    <parent link="l_SG_hip_back_left001"/>
    <child link="l_Spider_hipleg_backleft001"/>
    <origin rpy="3.141592653589793 0 0" xyz="-0.00718 0.0 -0.02828"/>
  </joint>
  <joint name="leg_backleft" type="revolute">
    <parent link="l_Spider_hipleg_backleft001"/>
    <child link="l_SG_leg_back_left001"/>
    <origin rpy="1.5707963267948963 0 0" xyz="-0.03856 -0.0175 -0.00984"/>
    <axis xyz="0 0 1"/>
    <limit effort="0.22" lower="-1.57" upper="1.57" velocity="10.0"/>
  </joint>
  <joint name="l_SG_hip_front_right001__to__l_Spider_hipleg_frontright001" type="fixed">
    <parent link="l_SG_hip_front_right001"/>
    <child link="l_Spider_hipleg_frontright001"/>
    <origin rpy="3.141592653589793 0 0" xyz="-0.00718 0.0 -0.02828"/>
  </joint>
  <joint name="leg_frontright" type="revolute">
    <parent link="l_Spider_hipleg_frontright001"/>
    <child link="l_SG_leg_front_right001"/>
    <origin rpy="1.5707963267948963 0 0" xyz="-0.03857 -0.0175 -0.01"/>
    <axis xyz="0 0 1"/>
    <limit effort="0.22" lower="-1.57" upper="1.57" velocity="10.0"/>
  </joint>
  <joint name="l_SG_hip_front_left001__to__l_Spider_hipleg_frontleft001" type="fixed">
    <parent link="l_SG_hip_front_left001"/>
    <child link="l_Spider_hipleg_frontleft001"/>
    <origin rpy="3.141592653589793 0 0" xyz="-0.00718 0.0 -0.02828"/>
  </joint>
  <joint name="leg_frontleft" type="revolute">
    <parent link="l_Spider_hipleg_frontleft001"/>
    <child link="l_SG_leg_front_left001"/>
    <origin rpy="1.5707963267948963 0 0" xyz="-0.03856 -0.0175 -0.01016"/>
    <axis xyz="0 0 1"/>
    <limit effort="0.22" lower="-1.57" upper="1.57" velocity="10.0"/>
  </joint>
  <joint name="l_SG_leg_back_right001__to__l_Spider_leg_backright001" type="fixed">
    <parent link="l_SG_leg_back_right001"/>
    <child link="l_Spider_leg_backright001"/>
    <origin rpy="-1.5707963267948966 0 -1.5707963267948966" xyz="-0.01136 0.0 -0.017"/>
  </joint>
  <joint name="l_Spider_leg_backright001__to__l_SG_foot_back_right001" type="fixed">
    <parent link="l_Spider_leg_backright001"/>
    <child link="l_SG_foot_back_right001"/>
    <origin rpy="1.5707963267948966 1.5707963267948966 0" xyz="0.01588 0.01275 -0.02965"/>
  </joint>
  <joint name="l_SG_leg_back_left001__to__l_Spider_leg_backleft001" type="fixed">
    <parent link="l_SG_leg_back_left001"/>
    <child link="l_Spider_leg_backleft001"/>
    <origin rpy="3.141592653589793 0 0" xyz="-0.00318 0.0 -0.02828"/>
  </joint>
  <joint name="l_Spider_leg_backleft001__to__l_SG_foot_back_left001" type="fixed">
    <parent link="l_Spider_leg_backleft001"/>
    <child link="l_SG_foot_back_left001"/>
    <origin rpy="-1.5707963267948968 0 0.872664625997165" xyz="-0.02727 0.0057 -0.00775"/>
  </joint>
  <joint name="l_SG_leg_front_right001__to__l_Spider_leg_frontright001" type="fixed">
    <parent link="l_SG_leg_front_right001"/>
    <child link="l_Spider_leg_frontright001"/>
    <origin rpy="3.141592653589793 0 0" xyz="-0.00318 0.0 -0.02828"/>
  </joint>
  <joint name="l_Spider_leg_frontright001__to__l_SG_foot_front_right001" type="fixed">
    <parent link="l_Spider_leg_frontright001"/>
    <child link="l_SG_foot_front_right001"/>
    <origin rpy="-1.5707963267948966 0 0.8726646259971649" xyz="-0.02727 0.0057 -0.00775"/>
  </joint>
  <joint name="l_SG_leg_front_left001__to__l_Spider_leg_frontleft001" type="fixed">
    <parent link="l_SG_leg_front_left001"/>
    <child link="l_Spider_leg_frontleft001"/>
    <origin rpy="3.141592653589793 0 0" xyz="-0.00318 0.0 -0.02828"/>
  </joint>
  <joint name="l_Spider_leg_frontleft001__to__l_SG_foot_front_left001" type="fixed">
    <parent link="l_Spider_leg_frontleft001"/>
    <child link="l_SG_foot_front_left001"/>
    <origin rpy="-1.5707963267948963 0 0.8726646259971647" xyz="-0.02727 0.0057 -0.00775"/>
  </joint>
  <joint name="foot_frontleft" type="revolute">
    <parent link="l_SG_foot_front_left001"/>
    <child link="l_Spider_foot_frontleft001"/>
    <origin rpy="1.5707963267948963 -0.2705980500730985 0" xyz="0.0 0.02 0.017"/>
    <axis xyz="0 0 1"/>
    <limit effort="0.22" lower="-1.57" upper="1.57" velocity="10.0"/>
  </joint>
  <joint name="foot_frontright" type="revolute">
    <parent link="l_SG_foot_front_right001"/>
    <child link="l_Spider_foot_frontright001"/>
    <origin rpy="1.5707963267948963 0.7853981633974483 0" xyz="0.0 0.02 0.017"/>
    <axis xyz="0 0 1"/>
    <limit effort="0.22" lower="-1.57" upper="1.57" velocity="10.0"/>
  </joint>
  <joint name="foot_backright" type="revolute">
    <parent link="l_SG_foot_back_right001"/>
    <child link="l_Spider_foot_backright001"/>
    <origin rpy="-3.1415926535897927 0 -3.141592653589793" xyz="-0.00184 -0.00046 0.02892"/>
    <axis xyz="0 0 1"/>
    <limit effort="0.22" lower="-1.57" upper="1.57" velocity="10.0"/>
  </joint>
  <joint name="foot_backleft" type="revolute">
    <parent link="l_SG_foot_back_left001"/>
    <child link="l_Spider_foot_backleft001"/>
    <origin rpy="1.5707963267948963 0.7853981633974483 0" xyz="0.0 0.02 0.017"/>
    <axis xyz="0 0 1"/>
    <limit effort="0.22" lower="-1.57" upper="1.57" velocity="10.0"/>
  </joint>

<!--
  <link name="l_cube">
    <visual>
      <origin xyz="0.2 0.2 0.2" rpy="0 0 0"/>
      <geometry>
        <box size="0.3 0.3 0.3"/>
      </geometry>
      <material name="blue">
        <color rgba="0 0 1 1"/>
      </material>
    </visual>
  </link>

  <joint name="cube_to_base" type="fixed">
    <parent link="l_Spider_base001"/>
    <child link="l_cube"/>
    <origin xyz="0 0 0" rpy="0 0 0"/>
  </joint>
 -->

  <gazebo>
      <plugin filename="libgz_ros2_control-system.so"
          name="gz_ros2_control::GazeboSimROS2ControlPlugin">
          <parameters>$(arg config_controllers)</parameters>
      </plugin>
  </gazebo>

  <!-- Revolute joints
  <transmission name="base_to_cupula_trans">
    <type>transmission_interface/SimpleTransmission</type>
    <joint name="base_to_cupula">
      <hardwareInterface>hardware_interface/PositionJointInterface</hardwareInterface>
      <hardwareInterface>hardware_interface/EffortJointInterface</hardwareInterface>
      <hardwareInterface>hardware_interface/VelocityJointInterface</hardwareInterface>
    </joint>
    <actuator name="base_to_cupula_motor">
      <hardwareInterface>hardware_interface/PositionJointInterface</hardwareInterface>
      <hardwareInterface>hardware_interface/EffortJointInterface</hardwareInterface>
      <hardwareInterface>hardware_interface/VelocityJointInterface</hardwareInterface>
    </actuator>
  </transmission> -->

  <!-- Revolute hip joints
  <transmission name="hip_backright_trans">
    <type>transmission_interface/SimpleTransmission</type>
    <joint name="hip_backright">
      <hardwareInterface>hardware_interface/PositionJointInterface</hardwareInterface>
      <hardwareInterface>hardware_interface/EffortJointInterface</hardwareInterface>
      <hardwareInterface>hardware_interface/VelocityJointInterface</hardwareInterface>
    </joint>
    <actuator name="hip_backright_motor">
      <hardwareInterface>hardware_interface/PositionJointInterface</hardwareInterface>
      <hardwareInterface>hardware_interface/EffortJointInterface</hardwareInterface>
      <hardwareInterface>hardware_interface/VelocityJointInterface</hardwareInterface>
    </actuator>
  </transmission> 

  <transmission name="hip_backleft_trans">
    <type>transmission_interface/SimpleTransmission</type>
    <joint name="hip_backleft">
      <hardwareInterface>hardware_interface/PositionJointInterface</hardwareInterface>
      <hardwareInterface>hardware_interface/EffortJointInterface</hardwareInterface>
      <hardwareInterface>hardware_interface/VelocityJointInterface</hardwareInterface>
    </joint>
    <actuator name="hip_backleft_motor">
      <hardwareInterface>hardware_interface/PositionJointInterface</hardwareInterface>
      <hardwareInterface>hardware_interface/EffortJointInterface</hardwareInterface>
      <hardwareInterface>hardware_interface/VelocityJointInterface</hardwareInterface>
    </actuator>
  </transmission>

  <transmission name="hip_frontright_trans">
    <type>transmission_interface/SimpleTransmission</type>
    <joint name="hip_frontright">
      <hardwareInterface>hardware_interface/PositionJointInterface</hardwareInterface>
      <hardwareInterface>hardware_interface/EffortJointInterface</hardwareInterface>
      <hardwareInterface>hardware_interface/VelocityJointInterface</hardwareInterface>
    </joint>
    <actuator name="hip_frontright_motor">
      <hardwareInterface>hardware_interface/PositionJointInterface</hardwareInterface>
      <hardwareInterface>hardware_interface/EffortJointInterface</hardwareInterface>
      <hardwareInterface>hardware_interface/VelocityJointInterface</hardwareInterface>
    </actuator>
  </transmission>

  <transmission name="hip_frontleft_trans">
    <type>transmission_interface/SimpleTransmission</type>
    <joint name="hip_frontleft">
      <hardwareInterface>hardware_interface/PositionJointInterface</hardwareInterface>
      <hardwareInterface>hardware_interface/EffortJointInterface</hardwareInterface>
      <hardwareInterface>hardware_interface/VelocityJointInterface</hardwareInterface>
    </joint>
    <actuator name="hip_frontleft_motor">
      <hardwareInterface>hardware_interface/PositionJointInterface</hardwareInterface>
      <hardwareInterface>hardware_interface/EffortJointInterface</hardwareInterface>
      <hardwareInterface>hardware_interface/VelocityJointInterface</hardwareInterface>
    </actuator>
  </transmission>  -->

  <!-- Revolute leg joints 
  <transmission name="leg_backright_trans">
    <type>transmission_interface/SimpleTransmission</type>
    <joint name="leg_backright">
      <hardwareInterface>hardware_interface/PositionJointInterface</hardwareInterface>
      <hardwareInterface>hardware_interface/EffortJointInterface</hardwareInterface>
      <hardwareInterface>hardware_interface/VelocityJointInterface</hardwareInterface>
    </joint>
    <actuator name="leg_backright_motor">
      <hardwareInterface>hardware_interface/PositionJointInterface</hardwareInterface>
      <hardwareInterface>hardware_interface/EffortJointInterface</hardwareInterface>
      <hardwareInterface>hardware_interface/VelocityJointInterface</hardwareInterface>
    </actuator>
  </transmission>

  <transmission name="leg_backleft_trans">
    <type>transmission_interface/SimpleTransmission</type>
    <joint name="leg_backleft">
      <hardwareInterface>hardware_interface/PositionJointInterface</hardwareInterface>
      <hardwareInterface>hardware_interface/EffortJointInterface</hardwareInterface>
      <hardwareInterface>hardware_interface/VelocityJointInterface</hardwareInterface>
    </joint>
    <actuator name="leg_backleft_motor">
      <hardwareInterface>hardware_interface/PositionJointInterface</hardwareInterface>
      <hardwareInterface>hardware_interface/EffortJointInterface</hardwareInterface>
      <hardwareInterface>hardware_interface/VelocityJointInterface</hardwareInterface>
    </actuator>
  </transmission>

  <transmission name="leg_frontright_trans">
    <type>transmission_interface/SimpleTransmission</type>
    <joint name="leg_frontright">
      <hardwareInterface>hardware_interface/PositionJointInterface</hardwareInterface>
      <hardwareInterface>hardware_interface/EffortJointInterface</hardwareInterface>
      <hardwareInterface>hardware_interface/VelocityJointInterface</hardwareInterface>
    </joint>
    <actuator name="leg_frontright_motor">
      <hardwareInterface>hardware_interface/PositionJointInterface</hardwareInterface>
      <hardwareInterface>hardware_interface/EffortJointInterface</hardwareInterface>
      <hardwareInterface>hardware_interface/VelocityJointInterface</hardwareInterface>
    </actuator>
  </transmission>

  <transmission name="leg_frontleft_trans">
    <type>transmission_interface/SimpleTransmission</type>
    <joint name="leg_frontleft">
      <hardwareInterface>hardware_interface/PositionJointInterface</hardwareInterface>
      <hardwareInterface>hardware_interface/EffortJointInterface</hardwareInterface>
      <hardwareInterface>hardware_interface/VelocityJointInterface</hardwareInterface>
    </joint>
    <actuator name="leg_frontleft_motor">
      <hardwareInterface>hardware_interface/PositionJointInterface</hardwareInterface>
      <hardwareInterface>hardware_interface/EffortJointInterface</hardwareInterface>
      <hardwareInterface>hardware_interface/VelocityJointInterface</hardwareInterface>
    </actuator>
  </transmission> -->

  <!-- Revolute foot joints 
  <transmission name="foot_frontleft_trans">
    <type>transmission_interface/SimpleTransmission</type>
    <joint name="foot_frontleft">
      <hardwareInterface>hardware_interface/PositionJointInterface</hardwareInterface>
      <hardwareInterface>hardware_interface/EffortJointInterface</hardwareInterface>
      <hardwareInterface>hardware_interface/VelocityJointInterface</hardwareInterface>
    </joint>
    <actuator name="foot_frontleft_motor">
      <hardwareInterface>hardware_interface/PositionJointInterface</hardwareInterface>
      <hardwareInterface>hardware_interface/EffortJointInterface</hardwareInterface>
      <hardwareInterface>hardware_interface/VelocityJointInterface</hardwareInterface>
    </actuator>
  </transmission>

  <transmission name="foot_frontright_trans">
    <type>transmission_interface/SimpleTransmission</type>
    <joint name="foot_frontright">
      <hardwareInterface>hardware_interface/PositionJointInterface</hardwareInterface>
      <hardwareInterface>hardware_interface/EffortJointInterface</hardwareInterface>
      <hardwareInterface>hardware_interface/VelocityJointInterface</hardwareInterface>
    </joint>
    <actuator name="foot_frontright_motor">
      <hardwareInterface>hardware_interface/PositionJointInterface</hardwareInterface>
      <hardwareInterface>hardware_interface/EffortJointInterface</hardwareInterface>
      <hardwareInterface>hardware_interface/VelocityJointInterface</hardwareInterface>
    </actuator>
  </transmission>

  <transmission name="foot_backright_trans">
    <type>transmission_interface/SimpleTransmission</type>
    <joint name="foot_backright">
      <hardwareInterface>hardware_interface/PositionJointInterface</hardwareInterface>
      <hardwareInterface>hardware_interface/EffortJointInterface</hardwareInterface>
      <hardwareInterface>hardware_interface/VelocityJointInterface</hardwareInterface>
    </joint>
    <actuator name="foot_backright_motor">
      <hardwareInterface>hardware_interface/PositionJointInterface</hardwareInterface>
      <hardwareInterface>hardware_interface/EffortJointInterface</hardwareInterface>
      <hardwareInterface>hardware_interface/VelocityJointInterface</hardwareInterface>
    </actuator>
  </transmission>

  <transmission name="foot_backleft_trans">
    <type>transmission_interface/SimpleTransmission</type>
    <joint name="foot_backleft">
      <hardwareInterface>hardware_interface/PositionJointInterface</hardwareInterface>
      <hardwareInterface>hardware_interface/EffortJointInterface</hardwareInterface>
      <hardwareInterface>hardware_interface/VelocityJointInterface</hardwareInterface>
    </joint>
    <actuator name="foot_backleft_motor">
      <hardwareInterface>hardware_interface/PositionJointInterface</hardwareInterface>
      <hardwareInterface>hardware_interface/EffortJointInterface</hardwareInterface>
      <hardwareInterface>hardware_interface/VelocityJointInterface</hardwareInterface>
    </actuator>
  </transmission> -->

  <ros2_control name="spider_hw" type="system">
    <hardware>
      <plugin>gz_ros2_control/GazeboSimSystem</plugin>
    </hardware>
    <joint name="base_to_cupula">
        <command_interface name="position" />
        
        <state_interface name="position" />
        <state_interface name="velocity" />
        <state_interface name="effort" />
    </joint>

    <joint name="hip_backright">
        <command_interface name="position" />
        
        <state_interface name="position" />
        <state_interface name="velocity" />
        <state_interface name="effort" />
    </joint>

    <joint name="hip_backleft">
        <command_interface name="position" />
        
        <state_interface name="position" />
        <state_interface name="velocity" />
        <state_interface name="effort" />
    </joint>

    <joint name="hip_frontright">
        <command_interface name="position" />
        
        <state_interface name="position" />
        <state_interface name="velocity" />
        <state_interface name="effort" />
    </joint>

    <joint name="hip_frontleft">
        <command_interface name="position" />
        
        <state_interface name="position" />
        <state_interface name="velocity" />
        <state_interface name="effort" />
    </joint>

    <joint name="leg_backright">
        <command_interface name="position" />
        
        <state_interface name="position" />
        <state_interface name="velocity" />
        <state_interface name="effort" />
    </joint>

    <joint name="leg_backleft">
        <command_interface name="position" />
        
        <state_interface name="position" />
        <state_interface name="velocity" />
        <state_interface name="effort" />
    </joint>

    <joint name="leg_frontright">
        <command_interface name="position" />
        
        <state_interface name="position" />
        <state_interface name="velocity" />
        <state_interface name="effort" />
    </joint>

    <joint name="leg_frontleft">
        <command_interface name="position" />
        
        <state_interface name="position" />
        <state_interface name="velocity" />
        <state_interface name="effort" />
    </joint>

    <joint name="foot_frontleft">
        <command_interface name="position" />
        
        <state_interface name="position" />
        <state_interface name="velocity" />
        <state_interface name="effort" />
    </joint>

    <joint name="foot_frontright">
        <command_interface name="position" />
        
        <state_interface name="position" />
        <state_interface name="velocity" />
        <state_interface name="effort" />
    </joint>

    <joint name="foot_backright">
        <command_interface name="position" />
        
        <state_interface name="position" />
        <state_interface name="velocity" />
        <state_interface name="effort" />
    </joint>

    <joint name="foot_backleft">
        <command_interface name="position" />
        
        <state_interface name="position" />
        <state_interface name="velocity" />
        <state_interface name="effort" />
    </joint>
  </ros2_control>
</robot>
